Workbook

Sheet Original data
A1: Dataset | B1: layer | C1: Valori unici nelle tabelle degli attributi | D1: Concatena | E1: Conteggio
A2: geoambientali | B2: AG_GEO_WGS | C2: superficie rocciosa ondulata da modellamento glaciale | D2: =_xlfn.CONCAT(A2,B2,C2) -> geoambientaliAG_GEO_WGSsuperficie rocciosa ondulata da modellamento glaciale | E2: 747
A3: geoambientali | B3: AG_GEO_WGS | C3: dolina | D3: =_xlfn.CONCAT(A3,B3,C3) -> geoambientaliAG_GEO_WGSdolina | E3: 358
A4: geoambientali | B4: AG_GEO_WGS | C4: ambito a forte dimamismo | D4: =_xlfn.CONCAT(A4,B4,C4) -> geoambientaliAG_GEO_WGSambito a forte dimamismo | E4: 1259
A5: geoambientali | B5: AG_GEO_WGS | C5: area interessata da diffusi fenomeni carsici | D5: =_xlfn.CONCAT(A5,B5,C5) -> geoambientaliAG_GEO_WGSarea interessata da diffusi fenomeni carsici | E5: 74
A6: geoambientali | B6: AG_GEO_WGS | C6: alveo abbandonato | D6: =_xlfn.CONCAT(A6,B6,C6) -> geoambientaliAG_GEO_WGSalveo abbandonato | E6: 76
A7: geoambientali | B7: AG_GEO_WGS | C7: area calanchiva | D7: =_xlfn.CONCAT(A7,B7,C7) -> geoambientaliAG_GEO_WGSarea calanchiva | E7: 85
A8: geoambientali | B8: AG_GEO_WGS | C8: superficie strutturale | D8: =_xlfn.CONCAT(A8,B8,C8) -> geoambientaliAG_GEO_WGSsuperficie strutturale | E8: 63
A9: geoambientali | B9: AG_GEO_WGS | C9: area di frane diffuse | D9: =_xlfn.CONCAT(A9,B9,C9) -> geoambientaliAG_GEO_WGSarea di frane diffuse | E9: 11
A10: geoambientali | B10: CA_GEO_WGS | C10: cascata | D10: =_xlfn.CONCAT(A10,B10,C10) -> geoambientaliCA_GEO_WGScascata | E10: 897
A11: geoambientali | B11: CO_GEO_WGS | C11: conoide di deiezione | D11: =_xlfn.CONCAT(A11,B11,C11) -> geoambientaliCO_GEO_WGSconoide di deiezione | E11: 3102
A12: geoambientali | B12: DS_GEO_WGS | C12: deposito | D12: =_xlfn.CONCAT(A12,B12,C12) -> geoambientaliDS_GEO_WGSdeposito | E12: 20164
A13: geoambientali | B13: DS_GEO_WGS | C13: detrito | D13: =_xlfn.CONCAT(A13,B13,C13) -> geoambientaliDS_GEO_WGSdetrito | E13: 19102
... A227: altri_dati | B227: WIZ_U32WG_VS_SIT_GEO_250K_F | C227: SOVRASCORRIMENTI | D227: =_xlfn.CONCAT(A227,B227,C227) -> altri_datiWIZ_U32WG_VS_SIT_GEO_250K_FSOVRASCORRIMENTI | E227: 444
A228: altri_dati | B228: WIZ_U32WG_CT10_UTM_TL_MSTR_TR_IDR | D228: =_xlfn.CONCAT(A228,B228,C228) -> altri_datiWIZ_U32WG_CT10_UTM_TL_MSTR_TR_IDR | E228: 139856
A229: DUSAF | B229: aree_fluviali_e_bacini | C229: Bacini idrici naturali | D229: =_xlfn.CONCAT(A229,B229,C229) -> DUSAFaree_fluviali_e_baciniBacini idrici naturali | E229: 2172
A230: DUSAF | B230: aree_fluviali_e_bacini | C230: Bacini idrici artificiali | D230: =_xlfn.CONCAT(A230,B230,C230) -> DUSAFaree_fluviali_e_baciniBacini idrici artificiali | E230: 1207
A231: DUSAF | B231: aree_fluviali_e_bacini | C231: Alvei fluviali e corsi d'acqua artificiali | D231: =_xlfn.CONCAT(A231,B231,C231) -> DUSAFaree_fluviali_e_baciniAlvei fluviali e corsi d'acqua artificiali | E231: 626
A232: DUSAF | B232: aree_fluviali_e_bacini | C232: Bacini idrici da attività estrattive interessanti la falda | D232: =_xlfn.CONCAT(A232,B232,C232) -> DUSAFaree_fluviali_e_baciniBacini idrici da attività estrattive interessanti la falda | E232: 365
A233: DUSAF | B233: cave_e_discariche | C233: cave | D233: =_xlfn.CONCAT(A233,B233,C233) -> DUSAFcave_e_discarichecave | E233: 645
A234: DUSAF | B234: cave_e_discariche | C234: discariche | D234: =_xlfn.CONCAT(A234,B234,C234) -> DUSAFcave_e_discarichediscariche | E234: 87
A235: DUSAF | B235: WIZ_U32WG_VS_DUSAF4 | C235: praterie naturali d'alta quota assenza di specie arboree ed arbustive | D235: =_xlfn.CONCAT(A235,B235,C235) -> DUSAFWIZ_U32WG_VS_DUSAF4praterie naturali d'alta quota assenza di specie arboree ed arbustive | E235: 2416
A236: DUSAF | B236: WIZ_U32WG_VS_DUSAF4 | C236: Boschi di conifere a densit?á bassa | D236: =_xlfn.CONCAT(A236,B236,C236) -> DUSAFWIZ_U32WG_VS_DUSAF4Boschi di conifere a densit?á bassa | E236: 1302
A237: DUSAF | B237: WIZ_U32WG_VS_DUSAF4 | C237: cespuglieti | D237: =_xlfn.CONCAT(A237,B237,C237) -> DUSAFWIZ_U32WG_VS_DUSAF4cespuglieti | E237: 3773
A238: DUSAF | B238: WIZ_U32WG_VS_DUSAF4 | C238: vegetazione rada | D238: =_xlfn.CONCAT(A238,B238,C238) -> DUSAFWIZ_U32WG_VS_DUSAF4vegetazione rada | E238: 5938
A239: DUSAF | B239: WIZ_U32WG_VS_DUSAF4 | C239: Accumuli detritici e affioramenti litoidi privi di vegetazione | D239: =_xlfn.CONCAT(A239,B239,C239) -> DUSAFWIZ_U32WG_VS_DUSAF4Accumuli detritici e affioramenti litoidi privi di vegetazione | E239: 5400
A240: DUSAF | B240: WIZ_U32WG_VS_DUSAF4 | C240: Insediamenti industriali, artigianali, commerciali | D240: =_xlfn.CONCAT(A240,B240,C240) -> DUSAFWIZ_U32WG_VS_DUSAF4Insediamenti industriali, artigianali, commerciali | E240: 15335
... A637: Opere_Difesa_Suolo | B637: ODS_TOT_linee | C637: iniezione/jet grouting | D637: =_xlfn.CONCAT(A637,B637,C637) -> Opere_Difesa_SuoloODS_TOT_lineeiniezione/jet grouting | E637: 1

Sheet Harmonised data
B1: Dataset | C1: Layer | D1: Data type | E1: Geomorphological (G) or not (N) | F1: Q13 morphogenetic process | G1: Values present in the original dataset | H1: Harmonisated nomenclature | I1: Acronimous Q13 | J1: Concatenato | K1: N. geometries | L1: Harmonisation | AA1: Q13 Morphogenetic processes | AB1: Acronymus
B2: dissesti_IFFI | C2: fr_aree | D2: GEOMORPHOLOGICAL DATA | E2: =IF(Tabella1[[#This Row],[Data type]]= "GEOMORPHOLOGICAL DATA", "G", "N") -> G | F2: AG | G2: 10 (Aree soggette a sprofondamenti diffusi) | H2: Sinkhole | I2: AG06 | J2: =_xlfn.CONCAT(B2,C2,G2) -> dissesti_IFFIfr_aree10 (Aree soggette a sprofondamenti diffusi) | K2: =_xlfn.XLOOKUP(Tabella1[[#This Row],[Concatenato]],'Original data'!D:D,'Original data'!E:E) -> 8867 | L2: F3 | AA2: Forme lito-strutturali | AB2: LS
B3: dissesti_IFFI | C3: fr_iffi | D3: GEOMORPHOLOGICAL DATA | E3: =IF(Tabella1[[#This Row],[Data type]]= "GEOMORPHOLOGICAL DATA", "G", "N") -> G | F3: AG | G3: 10 (Aree soggette a sprofondamenti diffusi) | H3: Sinkhole | I3: AG06 | J3: =_xlfn.CONCAT(B3,C3,G3) -> dissesti_IFFIfr_iffi10 (Aree soggette a sprofondamenti diffusi) | K3: =_xlfn.XLOOKUP(Tabella1[[#This Row],[Concatenato]],'Original data'!D:D,'Original data'!E:E) -> 6 | L3: F3 | R3: n. of successfully harmonised nomenclature | S3: =COUNTA(_xlfn.UNIQUE(I:I)) -> 72 | V3: harmonised geometries | W3: =SUMIF(I:I,"<>",K:K) -> 373901 | AA3: Forme tettoniche | AB3: TE | AO3: Direct correspondence with Q13 (D) | AP3: =COUNTIF(L:L,"D") -> 34 | AQ3: =SUMIF(L:L, "D", K:K) -> 8783
B4: geoambientali | C4: OS_GEP_WGS | D4: GEOMORPHOLOGICAL DATA | E4: =IF(Tabella1[[#This Row],[Data type]]= "GEOMORPHOLOGICAL DATA", "G", "N") -> G | F4: AN | G4: orlo di scarpata di origine antropica | H4: Scarpata di scavo | I4: AN01 | J4: =_xlfn.CONCAT(B4,C4,G4) -> geoambientaliOS_GEP_WGSorlo di scarpata di origine antropica | K4: =_xlfn.XLOOKUP(Tabella1[[#This Row],[Concatenato]],'Original data'!D:D,'Original data'!E:E) -> 6401 | L4: F3 | R4: n. unique value in the project | S4: =COUNTA(_xlfn.UNIQUE(G:G)) -> 418 | V4: all geometies in the dataset | W4: =SUM(K:K) -> 1119557 | AA4: Forme vulcaniche | AB4: VU | AO4: Lexical variation (e.g., singular/plural) (F1) | AP4: =COUNTIF(L:L,"F1") -> 3 | AQ4: =SUMIF(L:L, "F1", K:K) -> 2876
B5: geoambientali | C5: OS_GEP_WGS | D5: GEOMORPHOLOGICAL DATA | E5: =IF(Tabella1[[#This Row],[Data type]]= "GEOMORPHOLOGICAL DATA", "G", "N") -> G | F5: AN | G5: orlo di scarpata di cava o miniera a cielo aperto | H5: Scarpata di scavo | I5: AN01 | J5: =_xlfn.CONCAT(B5,C5,G5) -> geoambientaliOS_GEP_WGSorlo di scarpata di cava o miniera a cielo aperto | K5: =_xlfn.XLOOKUP(Tabella1[[#This Row],[Concatenato]],'Original data'!D:D,'Original data'!E:E) -> 568 | L5: F3 | R5: n.unique value not geomorphological | S5: {=SUM(IF((E2:E10000="N")*(G2:G10000<>""), 1/COUNTIF(G2:G10000, G2:G10000)))} -> 225 | V5: geometries not releated with geomorphology | W5: =SUMIF(E:E, "N", K:K) -> 568151 | AA5: Forme gravotative | AB5: GR | AO5: Lack of correspondence within Q13 (F2) | AP5: =COUNTIF(L:L,"F2") -> 27 | AQ5: =SUMIF(L:L, "F2", K:K) -> 220303
B6: DUSAF | C6: cave_e_discariche | D6: GEOMORPHOLOGICAL DATA | E6: =IF(Tabella1[[#This Row],[Data type]]= "GEOMORPHOLOGICAL DATA", "G", "N") -> G | F6: AN | G6: cave | H6: Cava/miniera a cielo aperto | I6: AN02 | J6: =_xlfn.CONCAT(B6,C6,G6) -> DUSAFcave_e_discarichecave | K6: =_xlfn.XLOOKUP(Tabella1[[#This Row],[Concatenato]],'Original data'!D:D,'Original data'!E:E) -> 645 | L6: D | AA6: Forme fluviali, fluvioglaciali, dovute al dilavamento | AB6: FD | AO6: Indirect correspondence (hyperonym → hyponym) (F3) | AP6: =COUNTIF(L:L,"F3") -> 103 | AQ6: =SUMIF(L:L, "F3", K:K) -> 140127
B7: DUSAF | C7: WIZ_U32WG_VS_DUSAF4 | D7: GEOMORPHOLOGICAL DATA | E7: =IF(Tabella1[[#This Row],[Data type]]= "GEOMORPHOLOGICAL DATA", "G", "N") -> G | F7: AN | G7: cave | H7: Cava/miniera a cielo aperto | I7: AN02 | J7: =_xlfn.CONCAT(B7,C7,G7) -> DUSAFWIZ_U32WG_VS_DUSAF4cave | K7: =_xlfn.XLOOKUP(Tabella1[[#This Row],[Concatenato]],'Original data'!D:D,'Original data'!E:E) -> 645 | L7: D | R7: N(%) | S7: =(S3/(S4-S5))*100 -> 37.305699 | V7: G(%) | W7: =(W3/(W4-W5))*100 -> 67.808656 | AA7: Forme carsiche | AB7: CA | AO7: Geomorphological feature not represented in Q13 (F4) | AP7: =COUNTIF(L:L,"F4") -> 193 | AQ7: =SUMIF(L:L, "F4", K:K) -> 177505
B8: geoambientali | C8: FA_CTRGEO_WGS | D8: GEOMORPHOLOGICAL DATA | E8: =IF(Tabella1[[#This Row],[Data type]]= "GEOMORPHOLOGICAL DATA", "G", "N") -> G | F8: AN | G8: cava | H8: Cava/miniera a cielo aperto | I8: AN02 | J8: =_xlfn.CONCAT(B8,C8,G8) -> geoambientaliFA_CTRGEO_WGScava | K8: =_xlfn.XLOOKUP(Tabella1[[#This Row],[Concatenato]],'Original data'!D:D,'Original data'!E:E) -> 313 | L8: F3 | AA8: Elementi del glavialismo e della nivazione attuali | AB8: GN | AO8: Not geomorfological features (NGMF) | AP8: =COUNTIF(L:L,"NGMF") -> 274 | AQ8: =SUMIF(L:L, "NGMF", K:K) -> 568151
B9: geoambientali | C9: FA_CTRGEO_WGS | D9: GEOMORPHOLOGICAL DATA | E9: =IF(Tabella1[[#This Row],[Data type]]= "GEOMORPHOLOGICAL DATA", "G", "N") -> G | F9: AN | G9: miniera | H9: Ingresso di cava/miniera sotterraneo | I9: AN04 | J9: =_xlfn.CONCAT(B9,C9,G9) -> geoambientaliFA_CTRGEO_WGSminiera | K9: =_xlfn.XLOOKUP(Tabella1[[#This Row],[Concatenato]],'Original data'!D:D,'Original data'!E:E) -> 219 | L9: F3 | AA9: Forme glaciali | AB9: GL
B10: geoambientali | C10: EP_CTRGEO_WGS | D10: GEOMORPHOLOGICAL DATA | E10: =IF(Tabella1[[#This Row],[Data type]]= "GEOMORPHOLOGICAL DATA", "G", "N") -> G | F10: AN | G10: miniera | H10: Ingresso di cava/miniera sotterraneo | I10: AN04 | J10: =_xlfn.CONCAT(B10,C10,G10) -> geoambientaliEP_CTRGEO_WGSminiera | K10: =_xlfn.XLOOKUP(Tabella1[[#This Row],[Concatenato]],'Original data'!D:D,'Original data'!E:E) -> 12 | L10: F3 | AA10: Forme periglaciali e nivali | AB10: PN
B11: geoambientali | C11: FA_CTRGEO_WGS | D11: GEOMORPHOLOGICAL DATA | E11: =IF(Tabella1[[#This Row],[Data type]]= "GEOMORPHOLOGICAL DATA", "G", "N") -> G | F11: AN | G11: discarica | H11: Area di discarica | I11: AN05 | J11: =_xlfn.CONCAT(B11,C11,G11) -> geoambientaliFA_CTRGEO_WGSdiscarica | K11: =_xlfn.XLOOKUP(Tabella1[[#This Row],[Concatenato]],'Original data'!D:D,'Original data'!E:E) -> 3235 | L11: F3 | AA11: Forme costiere | AB11: CO
B12: DUSAF | C12: cave_e_discariche | D12: GEOMORPHOLOGICAL DATA | E12: =IF(Tabella1[[#This Row],[Data type]]= "GEOMORPHOLOGICAL DATA", "G", "N") -> G | F12: AN | G12: discariche | H12: Area di discarica | I12: AN05 | J12: =_xlfn.CONCAT(B12,C12,G12) -> DUSAFcave_e_discarichediscariche | K12: =_xlfn.XLOOKUP(Tabella1[[#This Row],[Concatenato]],'Original data'!D:D,'Original data'!E:E) -> 87 | L12: F3 | AA12: Forme eoliche | AB12: EO
B13: DUSAF | C13: WIZ_U32WG_VS_DUSAF4 | D13: GEOMORPHOLOGICAL DATA | E13: =IF(Tabella1[[#This Row],[Data type]]= "GEOMORPHOLOGICAL DATA", "G", "N") -> G | F13: AN | G13: discariche | H13: Area di discarica | I13: AN05 | J13: =_xlfn.CONCAT(B13,C13,G13) -> DUSAFWIZ_U32WG_VS_DUSAF4discariche | K13: =_xlfn.XLOOKUP(Tabella1[[#This Row],[Concatenato]],'Original data'!D:D,'Original data'!E:E) -> 87 | L13: F3 | AA13: Forme di altra genesi | AB13: AG
B14: DUSAF | C14: aree_fluviali_e_bacini | D14: GEOMORPHOLOGICAL DATA | E14: =IF(Tabella1[[#This Row],[Data type]]= "GEOMORPHOLOGICAL DATA", "G", "N") -> G | F14: AN | G14: Bacini idrici artificiali | H14: Invaso artificiale | I14: AN20 | J14: =_xlfn.CONCAT(B14,C14,G14) -> DUSAFaree_fluviali_e_baciniBacini idrici artificiali | K14: =_xlfn.XLOOKUP(Tabella1[[#This Row],[Concatenato]],'Original data'!D:D,'Original data'!E:E) -> 1207 | L14: F3 | AA14: Forme antropiche | AB14: AN
B15: DUSAF | C15: WIZ_U32WG_VS_DUSAF4 | D15: GEOMORPHOLOGICAL DATA | E15: =IF(Tabella1[[#This Row],[Data type]]= "GEOMORPHOLOGICAL DATA", "G", "N") -> G | F15: AN | G15: Bacini idrici artificiali | H15: Invaso artificiale | I15: AN20 | J15: =_xlfn.CONCAT(B15,C15,G15) -> DUSAFWIZ_U32WG_VS_DUSAF4Bacini idrici artificiali | K15: =_xlfn.XLOOKUP(Tabella1[[#This Row],[Concatenato]],'Original data'!D:D,'Original data'!E:E) -> 1207 | L15: F3
B16: DUSAF | C16: WIZ_U32WG_VS_DUSAF4 | D16: GEOMORPHOLOGICAL DATA | E16: =IF(Tabella1[[#This Row],[Data type]]= "GEOMORPHOLOGICAL DATA", "G", "N") -> G | F16: AN | G16: Bacini idrici da attivit?? estrattive interessanti la falda | H16: Invaso artificiale | I16: AN20 | J16: =_xlfn.CONCAT(B16,C16,G16) -> DUSAFWIZ_U32WG_VS_DUSAF4Bacini idrici da attivit?? estrattive interessanti la falda | K16: =_xlfn.XLOOKUP(Tabella1[[#This Row],[Concatenato]],'Original data'!D:D,'Original data'!E:E) -> 365 | L16: F3
B17: DUSAF | C17: aree_fluviali_e_bacini | D17: GEOMORPHOLOGICAL DATA | E17: =IF(Tabella1[[#This Row],[Data type]]= "GEOMORPHOLOGICAL DATA", "G", "N") -> G | F17: AN | G17: Bacini idrici da attività estrattive interessanti la falda | H17: Invaso artificiale | I17: AN20 | J17: =_xlfn.CONCAT(B17,C17,G17) -> DUSAFaree_fluviali_e_baciniBacini idrici da attività estrattive interessanti la falda | K17: =_xlfn.XLOOKUP(Tabella1[[#This Row],[Concatenato]],'Original data'!D:D,'Original data'!E:E) -> 365 | L17: F3
B18: Opere_Difesa_Suolo | C18: ODS_TOT_linee | D18: GEOMORPHOLOGICAL DATA | E18: =IF(Tabella1[[#This Row],[Data type]]= "GEOMORPHOLOGICAL DATA", "G", "N") -> G | F18: AN | G18: argine | H18: Argine artificiale | I18: AN21 | J18: =_xlfn.CONCAT(B18,C18,G18) -> Opere_Difesa_SuoloODS_TOT_lineeargine | K18: =_xlfn.XLOOKUP(Tabella1[[#This Row],[Concatenato]],'Original data'!D:D,'Original data'!E:E) -> 3566 | L18: F3
B19: basi_ambientali_pianura | C19: WIZ_U32WG_VS_SIT_IDRO_ARGINI | D19: GEOMORPHOLOGICAL DATA | E19: =IF(Tabella1[[#This Row],[Data type]]= "GEOMORPHOLOGICAL DATA", "G", "N") -> G | F19: AN | G19: Argine maestro | H19: Argine artificiale | I19: AN21 | J19: =_xlfn.CONCAT(B19,C19,G19) -> basi_ambientali_pianuraWIZ_U32WG_VS_SIT_IDRO_ARGINIArgine maestro | K19: =_xlfn.XLOOKUP(Tabella1[[#This Row],[Concatenato]],'Original data'!D:D,'Original data'!E:E) -> 1150 | L19: F3
B20: basi_ambientali_pianura | C20: WIZ_U32WG_VS_SIT_IDRO_ARGINI | D20: GEOMORPHOLOGICAL DATA | E20: =IF(Tabella1[[#This Row],[Data type]]= "GEOMORPHOLOGICAL DATA", "G", "N") -> G | F20: AN | G20: Argine golenale | H20: Argine artificiale | I20: AN21 | J20: =_xlfn.CONCAT(B20,C20,G20) -> basi_ambientali_pianuraWIZ_U32WG_VS_SIT_IDRO_ARGINIArgine golenale | K20: =_xlfn.XLOOKUP(Tabella1[[#This Row],[Concatenato]],'Original data'!D:D,'Original data'!E:E) -> 746 | L20: F3
B21: Opere_Difesa_Suolo | C21: OPERE_FIUMI_PL | D21: GEOMORPHOLOGICAL DATA | E21: =IF(Tabella1[[#This Row],[Data type]]= "GEOMORPHOLOGICAL DATA", "G", "N") -> G | F21: AN | G21: argine | H21: Argine artificiale | I21: AN21 | J21: =_xlfn.CONCAT(B21,C21,G21) -> Opere_Difesa_SuoloOPERE_FIUMI_PLargine | K21: =_xlfn.XLOOKUP(Tabella1[[#This Row],[Concatenato]],'Original data'!D:D,'Original data'!E:E) -> 653 | L21: F3
B22: Opere_Difesa_Suolo | C22: ODS_TOT_punti | D22: GEOMORPHOLOGICAL DATA | E22: =IF(Tabella1[[#This Row],[Data type]]= "GEOMORPHOLOGICAL DATA", "G", "N") -> G | F22: AN | G22: argine | H22: Argine artificiale | I22: AN21 | J22: =_xlfn.CONCAT(B22,C22,G22) -> Opere_Difesa_SuoloODS_TOT_puntiargine | K22: =_xlfn.XLOOKUP(Tabella1[[#This Row],[Concatenato]],'Original data'!D:D,'Original data'!E:E) -> 384 | L22: F3
B23: basi_ambientali_pianura | C23: WIZ_U32WG_VS_SIT_IDRO_ARGINI | D23: GEOMORPHOLOGICAL DATA | E23: =IF(Tabella1[[#This Row],[Data type]]= "GEOMORPHOLOGICAL DATA", "G", "N") -> G | F23: AN | G23: Argine di sponda | H23: Argine artificiale | I23: AN21 | J23: =_xlfn.CONCAT(B23,C23,G23) -> basi_ambientali_pianuraWIZ_U32WG_VS_SIT_IDRO_ARGINIArgine di sponda | K23: =_xlfn.XLOOKUP(Tabella1[[#This Row],[Concatenato]],'Original data'!D:D,'Original data'!E:E) -> 284 | L23: F3
B24: Opere_Difesa_Suolo | C24: ODS_TOT_linee | D24: GEOMORPHOLOGICAL DATA | E24: =IF(Tabella1[[#This Row],[Data type]]= "GEOMORPHOLOGICAL DATA", "G", "N") -> G | F24: AN | G24: risagomatura alveo | H24: Argine artificiale | I24: AN21 | J24: =_xlfn.CONCAT(B24,C24,G24) -> Opere_Difesa_SuoloODS_TOT_lineerisagomatura alveo | K24: =_xlfn.XLOOKUP(Tabella1[[#This Row],[Concatenato]],'Original data'!D:D,'Original data'!E:E) -> 923 | L24: F3
B25: Opere_Difesa_Suolo | C25: ODS_TOT_aree | D25: GEOMORPHOLOGICAL DATA | E25: =IF(Tabella1[[#This Row],[Data type]]= "GEOMORPHOLOGICAL DATA", "G", "N") -> G | F25: AN | G25: risagomatura alveo | H25: Argine artificiale | I25: AN21 | J25: =_xlfn.CONCAT(B25,C25,G25) -> Opere_Difesa_SuoloODS_TOT_areerisagomatura alveo | K25: =_xlfn.XLOOKUP(Tabella1[[#This Row],[Concatenato]],'Original data'!D:D,'Original data'!E:E) -> 145 | L25: F3
B26: Opere_Difesa_Suolo | C26: ODS_TOT_punti | D26: GEOMORPHOLOGICAL DATA | E26: =IF(Tabella1[[#This Row],[Data type]]= "GEOMORPHOLOGICAL DATA", "G", "N") -> G | F26: AN | G26: risagomatura alveo | H26: Argine artificiale | I26: AN21 | J26: =_xlfn.CONCAT(B26,C26,G26) -> Opere_Difesa_SuoloODS_TOT_puntirisagomatura alveo | K26: =_xlfn.XLOOKUP(Tabella1[[#This Row],[Concatenato]],'Original data'!D:D,'Original data'!E:E) -> 32 | L26: F3
... B170: basi_ambientali_pianura | C170: WIZ_U32WG_VS_SIT_BASI_ELELIN | D170: GEOMORPHOLOGICAL DATA | E170: =IF(Tabella1[[#This Row],[Data type]]= "GEOMORPHOLOGICAL DATA", "G", "N") -> G | F170: TE | G170: Orlo di scarpata di origine tettonica | H170: Scarpata di faglia | I170: TE02 | J170: =_xlfn.CONCAT(B170,C170,G170) -> basi_ambientali_pianuraWIZ_U32WG_VS_SIT_BASI_ELELINOrlo di scarpata di origine tettonica | K170: =_xlfn.XLOOKUP(Tabella1[[#This Row],[Concatenato]],'Original data'!D:D,'Original data'!E:E) -> 7 | L170: F3
B171: altri_dati | C171: WIZ_U32WG_CT10_UTM_TL_MSTR_TR_IDR | D171: OTHER DATA | E171: =IF(Tabella1[[#This Row],[Data type]]= "GEOMORPHOLOGICAL DATA", "G", "N") -> N | J171: =_xlfn.CONCAT(B171,C171,G171) -> altri_datiWIZ_U32WG_CT10_UTM_TL_MSTR_TR_IDR | K171: =_xlfn.XLOOKUP(Tabella1[[#This Row],[Concatenato]],'Original data'!D:D,'Original data'!E:E) -> 139856 | L171: NGMF
B172: DUSAF | C172: WIZ_U32WG_VS_DUSAF4 | D172: LAND USE | E172: =IF(Tabella1[[#This Row],[Data type]]= "GEOMORPHOLOGICAL DATA", "G", "N") -> N | G172: prati permanenti in assenza di specie arboree ed arbustive | J172: =_xlfn.CONCAT(B172,C172,G172) -> DUSAFWIZ_U32WG_VS_DUSAF4prati permanenti in assenza di specie arboree ed arbustive | K172: =_xlfn.XLOOKUP(Tabella1[[#This Row],[Concatenato]],'Original data'!D:D,'Original data'!E:E) -> 43866 | L172: NGMF
B173: DUSAF | C173: WIZ_U32WG_VS_DUSAF4 | D173: LAND USE | E173: =IF(Tabella1[[#This Row],[Data type]]= "GEOMORPHOLOGICAL DATA", "G", "N") -> N | G173: Tessuto residenziale sparso | J173: =_xlfn.CONCAT(B173,C173,G173) -> DUSAFWIZ_U32WG_VS_DUSAF4Tessuto residenziale sparso | K173: =_xlfn.XLOOKUP(Tabella1[[#This Row],[Concatenato]],'Original data'!D:D,'Original data'!E:E) -> 23989 | L173: NGMF
B174: DUSAF | C174: WIZ_U32WG_VS_DUSAF4 | D174: LAND USE | E174: =IF(Tabella1[[#This Row],[Data type]]= "GEOMORPHOLOGICAL DATA", "G", "N") -> N | G174: seminativi semplici | J174: =_xlfn.CONCAT(B174,C174,G174) -> DUSAFWIZ_U32WG_VS_DUSAF4seminativi semplici | K174: =_xlfn.XLOOKUP(Tabella1[[#This Row],[Concatenato]],'Original data'!D:D,'Original data'!E:E) -> 20382 | L174: NGMF
B175: DUSAF | C175: WIZ_U32WG_VS_DUSAF4 | D175: LAND USE | E175: =IF(Tabella1[[#This Row],[Data type]]= "GEOMORPHOLOGICAL DATA", "G", "N") -> N | G175: Tessuto residenziale rado e nucleiforme | J175: =_xlfn.CONCAT(B175,C175,G175) -> DUSAFWIZ_U32WG_VS_DUSAF4Tessuto residenziale rado e nucleiforme | K175: =_xlfn.XLOOKUP(Tabella1[[#This Row],[Concatenato]],'Original data'!D:D,'Original data'!E:E) -> 19242 | L175: NGMF
B176: geoambientali | C176: SL_GEO_WGS | D176: LITHOLOGY | E176: =IF(Tabella1[[#This Row],[Data type]]= "GEOMORPHOLOGICAL DATA", "G", "N") -> N | G176: Gneiss | J176: =_xlfn.CONCAT(B176,C176,G176) -> geoambientaliSL_GEO_WGSGneiss | K176: =_xlfn.XLOOKUP(Tabella1[[#This Row],[Concatenato]],'Original data'!D:D,'Original data'!E:E) -> 18018 | L176: NGMF
B177: geoambientali | C177: SL_GEO_WGS | D177: LITHOLOGY | E177: =IF(Tabella1[[#This Row],[Data type]]= "GEOMORPHOLOGICAL DATA", "G", "N") -> N | G177: Calcare | J177: =_xlfn.CONCAT(B177,C177,G177) -> geoambientaliSL_GEO_WGSCalcare | K177: =_xlfn.XLOOKUP(Tabella1[[#This Row],[Concatenato]],'Original data'!D:D,'Original data'!E:E) -> 16112 | L177: NGMF
B178: geoambientali | C178: SL_GEO_WGS | D178: LITHOLOGY | E178: =IF(Tabella1[[#This Row],[Data type]]= "GEOMORPHOLOGICAL DATA", "G", "N") -> N | G178: Micascisti | J178: =_xlfn.CONCAT(B178,C178,G178) -> geoambientaliSL_GEO_WGSMicascisti | K178: =_xlfn.XLOOKUP(Tabella1[[#This Row],[Concatenato]],'Original data'!D:D,'Original data'!E:E) -> 15594 | L178: NGMF
B179: DUSAF | C179: WIZ_U32WG_VS_DUSAF4 | D179: LAND USE | E179: =IF(Tabella1[[#This Row],[Data type]]= "GEOMORPHOLOGICAL DATA", "G", "N") -> N | G179: Insediamenti industriali, artigianali, commerciali | J179: =_xlfn.CONCAT(B179,C179,G179) -> DUSAFWIZ_U32WG_VS_DUSAF4Insediamenti industriali, artigianali, commerciali | K179: =_xlfn.XLOOKUP(Tabella1[[#This Row],[Concatenato]],'Original data'!D:D,'Original data'!E:E) -> 15335 | L179: NGMF
B180: DUSAF | C180: WIZ_U32WG_VS_DUSAF4 | D180: LAND USE | E180: =IF(Tabella1[[#This Row],[Data type]]= "GEOMORPHOLOGICAL DATA", "G", "N") -> N | G180: boschi di latifoglie a densit?á media e alta | J180: =_xlfn.CONCAT(B180,C180,G180) -> DUSAFWIZ_U32WG_VS_DUSAF4boschi di latifoglie a densit?á media e alta | K180: =_xlfn.XLOOKUP(Tabella1[[#This Row],[Concatenato]],'Original data'!D:D,'Original data'!E:E) -> 14508 | L180: NGMF
B181: DUSAF | C181: WIZ_U32WG_VS_DUSAF4 | D181: LAND USE | E181: =IF(Tabella1[[#This Row],[Data type]]= "GEOMORPHOLOGICAL DATA", "G", "N") -> N | G181: Cascine | J181: =_xlfn.CONCAT(B181,C181,G181) -> DUSAFWIZ_U32WG_VS_DUSAF4Cascine | K181: =_xlfn.XLOOKUP(Tabella1[[#This Row],[Concatenato]],'Original data'!D:D,'Original data'!E:E) -> 13887 | L181: NGMF
B182: DUSAF | C182: WIZ_U32WG_VS_DUSAF4 | D182: LAND USE | E182: =IF(Tabella1[[#This Row],[Data type]]= "GEOMORPHOLOGICAL DATA", "G", "N") -> N | G182: Insediamenti produttivi agricoli | J182: =_xlfn.CONCAT(B182,C182,G182) -> DUSAFWIZ_U32WG_VS_DUSAF4Insediamenti produttivi agricoli | K182: =_xlfn.XLOOKUP(Tabella1[[#This Row],[Concatenato]],'Original data'!D:D,'Original data'!E:E) -> 13593 | L182: NGMF
B183: DUSAF | C183: WIZ_U32WG_VS_DUSAF4 | D183: LAND USE | E183: =IF(Tabella1[[#This Row],[Data type]]= "GEOMORPHOLOGICAL DATA", "G", "N") -> N | G183: cespuglieti in aree di agricole abbandonate | J183: =_xlfn.CONCAT(B183,C183,G183) -> DUSAFWIZ_U32WG_VS_DUSAF4cespuglieti in aree di agricole abbandonate | K183: =_xlfn.XLOOKUP(Tabella1[[#This Row],[Concatenato]],'Original data'!D:D,'Original data'!E:E) -> 12462 | L183: NGMF
...
